<?xml version="1.0" ?>
<!-- =================================================================================== -->
<!-- |    This document was autogenerated by xacro from rs007l_gripper.urdf.xacro      | -->
<!-- |    EDITING THIS FILE BY HAND IS NOT RECOMMENDED                                 | -->
<!-- =================================================================================== -->
<robot name="rs007l">
    <material name="White">
        <color rgba="1.0 1.0 1.0 1.0"/>
    </material>
    <material name="Black">
        <color rgba="0.0 0.0 0.0 1.0"/>
    </material>
    <link name="base_link">
        <visual>
          <geometry>
              <mesh filename="RS007L_J0.stl"/>
          </geometry>
          <material name="White"/>
          <origin rpy="0 0 0" xyz="0 0 0"/>
        </visual>
        <collision>
          <geometry>
              <mesh filename="RS007L_J0.stl"/>
          </geometry>
          <material name="White"/>
          <origin rpy="0 0 0" xyz="0 0 0"/>
        </collision>
        <inertial>
          <mass value="11"/>
          <inertia ixx="1.0" ixy="0.0" ixz="0.0" iyy="1.0" iyz="0.0" izz="1.0"/>
        </inertial>
    </link>
    <!-- Link 1 -->
    <joint name="joint1" type="revolute">
        <axis rpy="0 0 0" xyz="0 0 -1"/>
        <limit effort="1000.0" lower="-3.141592653589793" upper="3.141592653589793" velocity="6.457718232379019"/>
        <origin rpy="0 0 0" xyz="0 0 0.36"/>
        <parent link="base_link"/>
        <child link="link1"/>
        <dynamics damping="0.0" friction="0.0"/>
    </joint>
    <link name="link1">
        <visual>
          <geometry>
              <mesh filename="RS007L_J1.stl"/>
          </geometry>
          <material name="White"/>
          <origin rpy="0 0 0" xyz="0 0 0"/>
        </visual>
        <collision>
          <geometry>
              <mesh filename="RS007L_J1.stl"/>
          </geometry>
          <material name="White"/>
          <origin rpy="0 0 0" xyz="0 0 0"/>
        </collision>
        <inertial>
          <mass value="8.188"/>
          <inertia ixx="1.0" ixy="0.0" ixz="0.0" iyy="1.0" iyz="0.0" izz="1.0"/>
        </inertial>
    </link>
    <!-- Link 2 -->
    <joint name="joint2" type="revolute">
        <axis rpy="0 0 0" xyz="0 0 1"/>
        <limit effort="1000.0" lower="-2.356194490192345" upper="2.356194490192345" velocity="5.410520681182422"/>
        <origin rpy="0 -1.5707963267948966 0" xyz="0 0 0.0"/>
        <parent link="link1"/>
        <child link="link2"/>
        <dynamics damping="0.0" friction="0.0"/>
    </joint>
    <link name="link2">
        <visual>
          <geometry>
              <mesh filename="RS007L_J2.stl"/>
          </geometry>
          <material name="White"/>
          <origin rpy="0 1.5707963267948966 0" xyz="0 0 0"/>
        </visual>
        <collision>
          <geometry>
              <mesh filename="RS007L_J2.stl"/>
          </geometry>
          <material name="White"/>
          <origin rpy="0 1.5707963267948966 0" xyz="0 0 0"/>
        </collision>
        <inertial>
          <mass value="6.826"/>
          <inertia ixx="1.0" ixy="0.0" ixz="0.0" iyy="1.0" iyz="0.0" izz="1.0"/>
        </inertial>
    </link>
    <!-- Link 3 -->
    <joint name="joint3" type="revolute">
        <axis rpy="0 0 0" xyz="0 0 -1"/>
        <limit effort="1000.0" lower="-2.7401669256310974" upper="2.7401669256310974" velocity="7.155849933176751"/>
        <origin rpy="0 0 0" xyz="0.455 0 0"/>
        <parent link="link2"/>
        <child link="link3"/>
        <dynamics damping="0.0" friction="0.0"/>
    </joint>
    <link name="link3">
        <visual>
          <geometry>
              <mesh filename="RS007L_J3.stl"/>
          </geometry>
          <material name="White"/>
          <origin rpy="0 1.5707963267948966 0" xyz="0 0 0"/>
        </visual>
        <collision>
          <geometry>
              <mesh filename="RS007L_J3.stl"/>
          </geometry>
          <material name="White"/>
          <origin rpy="0 1.5707963267948966 0" xyz="0 0 0"/>
        </collision>
        <inertial>
          <mass value="5.236"/>
          <inertia ixx="1.0" ixy="0.0" ixz="0.0" iyy="1.0" iyz="0.0" izz="1.0"/>
        </inertial>
    </link>
    <!-- Link 4 -->
    <joint name="joint4" type="revolute">
        <axis rpy="0 0 0" xyz="0 0 1"/>
        <limit effort="1000.0" lower="-3.490658503988659" upper="3.490658503988659" velocity="9.599310885968812"/>
        <origin rpy="0 1.5707963267948966 0" xyz="0.0925 0 0"/>
        <parent link="link3"/>
        <child link="link4"/>
        <dynamics damping="0.0" friction="0.0"/>
    </joint>
    <link name="link4">
        <visual>
          <geometry>
              <mesh filename="RS007L_J4.stl"/>
          </geometry>
          <material name="White"/>
          <origin rpy="0 0 0" xyz="0 0 0.3825"/>
        </visual>
        <collision>
          <geometry>
              <mesh filename="RS007L_J4.stl"/>
          </geometry>
          <material name="White"/>
          <origin rpy="0 0 0" xyz="0 0 0.3825"/>
        </collision>
        <inertial>
          <mass value="5.066"/>
          <inertia ixx="1.0" ixy="0.0" ixz="0.0" iyy="1.0" iyz="0.0" izz="1.0"/>
        </inertial>
    </link>
    <!-- Link 5 -->
    <joint name="joint5" type="revolute">
        <axis rpy="0 0 0" xyz="0 0 -1"/>
        <limit effort="1000.0" lower="-2.181661564992912" upper="2.181661564992912" velocity="9.599310885968812"/>
        <origin rpy="0 -1.5707963267948966 0" xyz="0 0 0.3825"/>
        <parent link="link4"/>
        <child link="link5"/>
        <dynamics damping="0.0" friction="0.0"/>
    </joint>
    <link name="link5">
        <visual>
          <geometry>
              <mesh filename="RS007L_J5.stl"/>
          </geometry>
          <material name="White"/>
          <origin rpy="0 1.5707963267948966 0" xyz="0 0 0"/>
        </visual>
        <collision>
          <geometry>
              <mesh filename="RS007L_J5.stl"/>
          </geometry>
          <material name="White"/>
          <origin rpy="0 1.5707963267948966 0" xyz="0 0 0"/>
        </collision>
        <inertial>
          <mass value="1.625"/>
          <inertia ixx="1.0" ixy="0.0" ixz="0.0" iyy="1.0" iyz="0.0" izz="1.0"/>
        </inertial>
    </link>
    <!-- Link 6 -->
    <joint name="joint6" type="revolute">
        <axis rpy="0 0 0" xyz="0 0 1"/>
        <limit effort="1000.0" lower="-6.283185307179586" upper="6.283185307179586" velocity="17.453292519943297"/>
        <origin rpy="0 1.5707963267948966 0" xyz="0.078 0 0"/>
        <parent link="link5"/>
        <child link="link6"/>
        <dynamics damping="0.0" friction="0.0"/>
    </joint>
    <link name="link6">
        <visual>
          <geometry>
              <mesh filename="RS007L_J6.stl"/>
          </geometry>
          <material name="Black"/>
          <origin rpy="0 0 0" xyz="0 0 0"/>
        </visual>
        <collision>
          <geometry>
              <mesh filename="RS007L_J6.stl"/>
          </geometry>
          <material name="Black"/>
          <origin rpy="0 0 0" xyz="0 0 0"/>
        </collision>
        <inertial>
          <mass value="0.625"/>
          <inertia ixx="1.0" ixy="0.0" ixz="0.0" iyy="1.0" iyz="0.0" izz="1.0"/>
        </inertial>
    </link>
    <joint name="ee_fixed_joint" type="fixed">
        <parent link="link6"/>
        <child link="ee_link"/>
        <origin rpy="0.0 0.0 1.57079632679" xyz="0.0 0.1 0.0"/>
    </joint>
    <link name="ee_link">
        <!-- <collision>
            <geometry>
                <box size="0.01 0.01 0.01"/>
            </geometry>
            <origin rpy="0 0 0" xyz="-0.01 0 0"/>
        </collision> -->
    </link>
    <transmission name="joint1_trans">
        <type>transmission_interface/SimpleTransmission</type>
        <actuator name="joint1_motor">
          <hardwareInterface>hardware_interface/PositionJointInterface</hardwareInterface>
          <mechanicalReduction>1</mechanicalReduction>
        </actuator>
        <joint name="joint1">
          <hardwareInterface>hardware_interface/PositionJointInterface</hardwareInterface>
        </joint>
    </transmission>
    <transmission name="joint2_trans">
        <type>transmission_interface/SimpleTransmission</type>
        <actuator name="joint2_motor">
          <hardwareInterface>hardware_interface/PositionJointInterface</hardwareInterface>
          <mechanicalReduction>1</mechanicalReduction>
        </actuator>
        <joint name="joint2">
          <hardwareInterface>hardware_interface/PositionJointInterface</hardwareInterface>
        </joint>
    </transmission>
    <transmission name="joint3_trans">
        <type>transmission_interface/SimpleTransmission</type>
        <actuator name="joint3_motor">
          <hardwareInterface>hardware_interface/PositionJointInterface</hardwareInterface>
          <mechanicalReduction>1</mechanicalReduction>
        </actuator>
        <joint name="joint3">
          <hardwareInterface>hardware_interface/PositionJointInterface</hardwareInterface>
        </joint>
    </transmission>
    <transmission name="joint4_trans">
        <type>transmission_interface/SimpleTransmission</type>
        <actuator name="joint4_motor">
          <hardwareInterface>hardware_interface/PositionJointInterface</hardwareInterface>
          <mechanicalReduction>1</mechanicalReduction>
        </actuator>
        <joint name="joint4">
          <hardwareInterface>hardware_interface/PositionJointInterface</hardwareInterface>
        </joint>
    </transmission>
    <transmission name="joint5_trans">
        <type>transmission_interface/SimpleTransmission</type>
        <actuator name="joint5_motor">
          <hardwareInterface>hardware_interface/PositionJointInterface</hardwareInterface>
          <mechanicalReduction>1</mechanicalReduction>
        </actuator>
        <joint name="joint5">
          <hardwareInterface>hardware_interface/PositionJointInterface</hardwareInterface>
        </joint>
    </transmission>
    <transmission name="joint6_trans">
        <type>transmission_interface/SimpleTransmission</type>
        <actuator name="joint6_motor">
          <hardwareInterface>hardware_interface/PositionJointInterface</hardwareInterface>
          <mechanicalReduction>1</mechanicalReduction>
        </actuator>
        <joint name="joint6">
          <hardwareInterface>hardware_interface/PositionJointInterface</hardwareInterface>
        </joint>
    </transmission>
    <!-- ROS base_link to UR 'Base' Coordinates transform -->
    <link name="base"/>
    <joint name="base-base_link_fixed_joint" type="fixed">
        <!-- NOTE: this rotation is only needed as long as base_link itself is
                     not corrected wrt the real robot (ie: rotated over 180
                     degrees)
          -->
        <origin rpy="0 0 0" xyz="0 0 0"/>
        <parent link="base"/>
        <child link="base_link"/>
    </joint>
    <!-- Frame coincident with all-zeros TCP on UR controller -->
    <link name="tool0"/>
    <joint name="link6-tool0_fixed_joint" type="fixed">
        <!-- <origin rpy="-1.57079632679 0 0" xyz="0 0.1 0"/> -->
        <origin rpy="0 0 0" xyz="0 0 0"/>
        <parent link="link6"/>
        <child link="tool0"/>
    </joint>
    <link name="world"/>
    <joint name="world_joint" type="fixed">
        <parent link="world"/>
        <child link="base"/>
        <origin rpy="0.0 0.0 0.0" xyz="0.0 0.0 0.0"/>
    </joint>
</robot>
